Traceback (most recent call last):
  File "./exploits/case16.py", line 27, in <module>
    driver.close()
  File "/usr/local/lib/python2.7/dist-packages/selenium/webdriver/remote/webdriver.py", line 679, in close
    self.execute(Command.CLOSE)
  File "/usr/local/lib/python2.7/dist-packages/selenium/webdriver/remote/webdriver.py", line 312, in execute
    self.error_handler.check_response(response)
  File "/usr/local/lib/python2.7/dist-packages/selenium/webdriver/remote/errorhandler.py", line 241, in check_response
    raise exception_class(message, screen, stacktrace, alert_text)
selenium.common.exceptions.UnexpectedAlertPresentException: Alert Text: None
Message: 

